[2021-06-17 15:31:47,548] ERROR in app: Exception on /farmer [POST]
Traceback (most recent call last):
  File "/home/user/.local/lib/python3.6/site-packages/flask/app.py", line 1513, in full_dispatch_request
    rv = self.dispatch_request()
  File "/home/user/.local/lib/python3.6/site-packages/flask/app.py", line 1499, in dispatch_request
    return self.ensure_sync(self.view_functions[rule.endpoint])(**req.view_args)
  File "/home/user/.local/lib/python3.6/site-packages/flask_restful/__init__.py", line 467, in wrapper
    resp = resource(*args, **kwargs)
  File "/home/user/.local/lib/python3.6/site-packages/flask/views.py", line 83, in view
    return self.dispatch_request(*args, **kwargs)
  File "/home/user/.local/lib/python3.6/site-packages/flask_restful/__init__.py", line 582, in dispatch_request
    resp = meth(*args, **kwargs)
  File "/home/user/agrostar-workspace/farmerservice_flask/farmerservice/handler/farmerHandler.py", line 8, in post
    request_data = request.json
AttributeError: 'FarmerHandler' object has no attribute 'json'
[2021-06-17 15:36:57,155] ERROR in app: Exception on /getfarmer [GET]
Traceback (most recent call last):
  File "/home/user/.local/lib/python3.6/site-packages/flask/app.py", line 1513, in full_dispatch_request
    rv = self.dispatch_request()
  File "/home/user/.local/lib/python3.6/site-packages/flask/app.py", line 1499, in dispatch_request
    return self.ensure_sync(self.view_functions[rule.endpoint])(**req.view_args)
  File "/home/user/.local/lib/python3.6/site-packages/flask_restful/__init__.py", line 467, in wrapper
    resp = resource(*args, **kwargs)
  File "/home/user/.local/lib/python3.6/site-packages/flask/views.py", line 83, in view
    return self.dispatch_request(*args, **kwargs)
  File "/home/user/.local/lib/python3.6/site-packages/flask_restful/__init__.py", line 582, in dispatch_request
    resp = meth(*args, **kwargs)
  File "/home/user/agrostar-workspace/farmerservice_flask/farmerservice/handler/farmerHandler.py", line 22, in get
    resp = get_farmer(request_data)
  File "/home/user/agrostar-workspace/farmerservice_flask/farmerservice/views/farmerController.py", line 89, in get_farmer
    phone_number = request_param.get("phone_no")
AttributeError: 'function' object has no attribute 'get'
[2021-06-17 15:39:04,121] ERROR in app: Exception on /farmer [POST]
Traceback (most recent call last):
  File "/home/user/.local/lib/python3.6/site-packages/flask/app.py", line 1513, in full_dispatch_request
    rv = self.dispatch_request()
  File "/home/user/.local/lib/python3.6/site-packages/flask/app.py", line 1499, in dispatch_request
    return self.ensure_sync(self.view_functions[rule.endpoint])(**req.view_args)
  File "/home/user/.local/lib/python3.6/site-packages/flask_restful/__init__.py", line 467, in wrapper
    resp = resource(*args, **kwargs)
  File "/home/user/.local/lib/python3.6/site-packages/flask/views.py", line 83, in view
    return self.dispatch_request(*args, **kwargs)
  File "/home/user/.local/lib/python3.6/site-packages/flask_restful/__init__.py", line 582, in dispatch_request
    resp = meth(*args, **kwargs)
  File "/home/user/agrostar-workspace/farmerservice_flask/farmerservice/handler/farmerHandler.py", line 8, in post
    request_data = request.json
AttributeError: 'FarmerHandler' object has no attribute 'json'
[2021-06-17 15:39:14,500] ERROR in app: Exception on /getfarmer [GET]
Traceback (most recent call last):
  File "/home/user/.local/lib/python3.6/site-packages/flask/app.py", line 1513, in full_dispatch_request
    rv = self.dispatch_request()
  File "/home/user/.local/lib/python3.6/site-packages/flask/app.py", line 1499, in dispatch_request
    return self.ensure_sync(self.view_functions[rule.endpoint])(**req.view_args)
  File "/home/user/.local/lib/python3.6/site-packages/flask_restful/__init__.py", line 467, in wrapper
    resp = resource(*args, **kwargs)
  File "/home/user/.local/lib/python3.6/site-packages/flask/views.py", line 83, in view
    return self.dispatch_request(*args, **kwargs)
  File "/home/user/.local/lib/python3.6/site-packages/flask_restful/__init__.py", line 582, in dispatch_request
    resp = meth(*args, **kwargs)
  File "/home/user/agrostar-workspace/farmerservice_flask/farmerservice/handler/farmerHandler.py", line 22, in get
    request_data = self.get
  File "/home/user/agrostar-workspace/farmerservice_flask/farmerservice/views/farmerController.py", line 89, in get_farmer
    phone_number = request_param.get("phone_no")
AttributeError: 'function' object has no attribute 'get'
[2021-06-17 15:39:49,687] ERROR in app: Exception on /shippingAddress [GET]
Traceback (most recent call last):
  File "/home/user/.local/lib/python3.6/site-packages/flask/app.py", line 1513, in full_dispatch_request
    rv = self.dispatch_request()
  File "/home/user/.local/lib/python3.6/site-packages/flask/app.py", line 1499, in dispatch_request
    return self.ensure_sync(self.view_functions[rule.endpoint])(**req.view_args)
  File "/home/user/.local/lib/python3.6/site-packages/flask_restful/__init__.py", line 467, in wrapper
    resp = resource(*args, **kwargs)
  File "/home/user/.local/lib/python3.6/site-packages/flask/views.py", line 83, in view
    return self.dispatch_request(*args, **kwargs)
  File "/home/user/.local/lib/python3.6/site-packages/flask_restful/__init__.py", line 582, in dispatch_request
    resp = meth(*args, **kwargs)
  File "/home/user/agrostar-workspace/farmerservice_flask/farmerservice/handler/shippingAddressHandler.py", line 14, in get
    resp = get_shipping_address(request_data)
  File "/home/user/agrostar-workspace/farmerservice_flask/farmerservice/views/shippingController.py", line 37, in get_shipping_address
    phone_number= request_param.get("phone_no")
AttributeError: 'function' object has no attribute 'get'
[2021-06-17 15:45:11,985] ERROR in app: Exception on /shippingAddress [GET]
Traceback (most recent call last):
  File "/home/user/.local/lib/python3.6/site-packages/flask/app.py", line 1513, in full_dispatch_request
    rv = self.dispatch_request()
  File "/home/user/.local/lib/python3.6/site-packages/flask/app.py", line 1499, in dispatch_request
    return self.ensure_sync(self.view_functions[rule.endpoint])(**req.view_args)
  File "/home/user/.local/lib/python3.6/site-packages/flask_restful/__init__.py", line 467, in wrapper
    resp = resource(*args, **kwargs)
  File "/home/user/.local/lib/python3.6/site-packages/flask/views.py", line 83, in view
    return self.dispatch_request(*args, **kwargs)
  File "/home/user/.local/lib/python3.6/site-packages/flask_restful/__init__.py", line 582, in dispatch_request
    resp = meth(*args, **kwargs)
  File "/home/user/agrostar-workspace/farmerservice_flask/farmerservice/handler/shippingAddressHandler.py", line 14, in get
    resp = get_shipping_address(request_data)
  File "/home/user/agrostar-workspace/farmerservice_flask/farmerservice/views/shippingController.py", line 37, in get_shipping_address
    #get the farmer object
AttributeError: 'function' object has no attribute 'get'
[2021-06-17 15:53:30,999] ERROR in app: Exception on /shippingAddress [GET]
Traceback (most recent call last):
  File "/home/user/.local/lib/python3.6/site-packages/flask/app.py", line 1513, in full_dispatch_request
    rv = self.dispatch_request()
  File "/home/user/.local/lib/python3.6/site-packages/flask/app.py", line 1499, in dispatch_request
    return self.ensure_sync(self.view_functions[rule.endpoint])(**req.view_args)
  File "/home/user/.local/lib/python3.6/site-packages/flask_restful/__init__.py", line 467, in wrapper
    resp = resource(*args, **kwargs)
  File "/home/user/.local/lib/python3.6/site-packages/flask/views.py", line 83, in view
    return self.dispatch_request(*args, **kwargs)
  File "/home/user/.local/lib/python3.6/site-packages/flask_restful/__init__.py", line 582, in dispatch_request
    resp = meth(*args, **kwargs)
  File "/home/user/agrostar-workspace/farmerservice_flask/farmerservice/handler/shippingAddressHandler.py", line 14, in get
    resp = get_shipping_address(request_data)
  File "/home/user/agrostar-workspace/farmerservice_flask/farmerservice/views/shippingController.py", line 37, in get_shipping_address
    #get the farmer object
AttributeError: 'function' object has no attribute 'get'
[2021-06-17 15:55:39,301] ERROR in app: Exception on /shippingAddress [GET]
Traceback (most recent call last):
  File "/home/user/.local/lib/python3.6/site-packages/flask/app.py", line 1513, in full_dispatch_request
    rv = self.dispatch_request()
  File "/home/user/.local/lib/python3.6/site-packages/flask/app.py", line 1499, in dispatch_request
    return self.ensure_sync(self.view_functions[rule.endpoint])(**req.view_args)
  File "/home/user/.local/lib/python3.6/site-packages/flask_restful/__init__.py", line 467, in wrapper
    resp = resource(*args, **kwargs)
  File "/home/user/.local/lib/python3.6/site-packages/flask/views.py", line 83, in view
    return self.dispatch_request(*args, **kwargs)
  File "/home/user/.local/lib/python3.6/site-packages/flask_restful/__init__.py", line 582, in dispatch_request
    resp = meth(*args, **kwargs)
  File "/home/user/agrostar-workspace/farmerservice_flask/farmerservice/handler/shippingAddressHandler.py", line 14, in get
    resp = get_shipping_address(request_data)
  File "/home/user/agrostar-workspace/farmerservice_flask/farmerservice/views/shippingController.py", line 37, in get_shipping_address
    #get the farmer object
AttributeError: 'function' object has no attribute 'get'
[2021-06-17 15:55:41,017] ERROR in app: Exception on /shippingAddress [GET]
Traceback (most recent call last):
  File "/home/user/.local/lib/python3.6/site-packages/flask/app.py", line 1513, in full_dispatch_request
    rv = self.dispatch_request()
  File "/home/user/.local/lib/python3.6/site-packages/flask/app.py", line 1499, in dispatch_request
    return self.ensure_sync(self.view_functions[rule.endpoint])(**req.view_args)
  File "/home/user/.local/lib/python3.6/site-packages/flask_restful/__init__.py", line 467, in wrapper
    resp = resource(*args, **kwargs)
  File "/home/user/.local/lib/python3.6/site-packages/flask/views.py", line 83, in view
    return self.dispatch_request(*args, **kwargs)
  File "/home/user/.local/lib/python3.6/site-packages/flask_restful/__init__.py", line 582, in dispatch_request
    resp = meth(*args, **kwargs)
  File "/home/user/agrostar-workspace/farmerservice_flask/farmerservice/handler/shippingAddressHandler.py", line 14, in get
    resp = get_shipping_address(request_data)
  File "/home/user/agrostar-workspace/farmerservice_flask/farmerservice/views/shippingController.py", line 37, in get_shipping_address
    #get the farmer object
AttributeError: 'function' object has no attribute 'get'
[2021-06-17 15:55:41,976] ERROR in app: Exception on /shippingAddress [GET]
Traceback (most recent call last):
  File "/home/user/.local/lib/python3.6/site-packages/flask/app.py", line 1513, in full_dispatch_request
    rv = self.dispatch_request()
  File "/home/user/.local/lib/python3.6/site-packages/flask/app.py", line 1499, in dispatch_request
    return self.ensure_sync(self.view_functions[rule.endpoint])(**req.view_args)
  File "/home/user/.local/lib/python3.6/site-packages/flask_restful/__init__.py", line 467, in wrapper
    resp = resource(*args, **kwargs)
  File "/home/user/.local/lib/python3.6/site-packages/flask/views.py", line 83, in view
    return self.dispatch_request(*args, **kwargs)
  File "/home/user/.local/lib/python3.6/site-packages/flask_restful/__init__.py", line 582, in dispatch_request
    resp = meth(*args, **kwargs)
  File "/home/user/agrostar-workspace/farmerservice_flask/farmerservice/handler/shippingAddressHandler.py", line 14, in get
    resp = get_shipping_address(request_data)
  File "/home/user/agrostar-workspace/farmerservice_flask/farmerservice/views/shippingController.py", line 37, in get_shipping_address
    #get the farmer object
AttributeError: 'function' object has no attribute 'get'
[2021-06-17 15:55:42,425] ERROR in app: Exception on /shippingAddress [GET]
Traceback (most recent call last):
  File "/home/user/.local/lib/python3.6/site-packages/flask/app.py", line 1513, in full_dispatch_request
    rv = self.dispatch_request()
  File "/home/user/.local/lib/python3.6/site-packages/flask/app.py", line 1499, in dispatch_request
    return self.ensure_sync(self.view_functions[rule.endpoint])(**req.view_args)
  File "/home/user/.local/lib/python3.6/site-packages/flask_restful/__init__.py", line 467, in wrapper
    resp = resource(*args, **kwargs)
  File "/home/user/.local/lib/python3.6/site-packages/flask/views.py", line 83, in view
    return self.dispatch_request(*args, **kwargs)
  File "/home/user/.local/lib/python3.6/site-packages/flask_restful/__init__.py", line 582, in dispatch_request
    resp = meth(*args, **kwargs)
  File "/home/user/agrostar-workspace/farmerservice_flask/farmerservice/handler/shippingAddressHandler.py", line 14, in get
    resp = get_shipping_address(request_data)
  File "/home/user/agrostar-workspace/farmerservice_flask/farmerservice/views/shippingController.py", line 37, in get_shipping_address
    #get the farmer object
AttributeError: 'function' object has no attribute 'get'
[2021-06-17 15:55:43,064] ERROR in app: Exception on /shippingAddress [GET]
Traceback (most recent call last):
  File "/home/user/.local/lib/python3.6/site-packages/flask/app.py", line 1513, in full_dispatch_request
    rv = self.dispatch_request()
  File "/home/user/.local/lib/python3.6/site-packages/flask/app.py", line 1499, in dispatch_request
    return self.ensure_sync(self.view_functions[rule.endpoint])(**req.view_args)
  File "/home/user/.local/lib/python3.6/site-packages/flask_restful/__init__.py", line 467, in wrapper
    resp = resource(*args, **kwargs)
  File "/home/user/.local/lib/python3.6/site-packages/flask/views.py", line 83, in view
    return self.dispatch_request(*args, **kwargs)
  File "/home/user/.local/lib/python3.6/site-packages/flask_restful/__init__.py", line 582, in dispatch_request
    resp = meth(*args, **kwargs)
  File "/home/user/agrostar-workspace/farmerservice_flask/farmerservice/handler/shippingAddressHandler.py", line 14, in get
    resp = get_shipping_address(request_data)
  File "/home/user/agrostar-workspace/farmerservice_flask/farmerservice/views/shippingController.py", line 37, in get_shipping_address
    #get the farmer object
AttributeError: 'function' object has no attribute 'get'
[2021-06-17 15:56:32,784] ERROR in app: Exception on /shippingAddress [GET]
Traceback (most recent call last):
  File "/home/user/.local/lib/python3.6/site-packages/flask/app.py", line 1513, in full_dispatch_request
    rv = self.dispatch_request()
  File "/home/user/.local/lib/python3.6/site-packages/flask/app.py", line 1499, in dispatch_request
    return self.ensure_sync(self.view_functions[rule.endpoint])(**req.view_args)
  File "/home/user/.local/lib/python3.6/site-packages/flask_restful/__init__.py", line 467, in wrapper
    resp = resource(*args, **kwargs)
  File "/home/user/.local/lib/python3.6/site-packages/flask/views.py", line 83, in view
    return self.dispatch_request(*args, **kwargs)
  File "/home/user/.local/lib/python3.6/site-packages/flask_restful/__init__.py", line 582, in dispatch_request
    resp = meth(*args, **kwargs)
  File "/home/user/agrostar-workspace/farmerservice_flask/farmerservice/handler/shippingAddressHandler.py", line 14, in get
    resp = get_shipping_address(request_data)
  File "/home/user/agrostar-workspace/farmerservice_flask/farmerservice/views/shippingController.py", line 37, in get_shipping_address
    #get the farmer object
AttributeError: 'function' object has no attribute 'get'
[2021-06-17 15:57:11,106] ERROR in app: Exception on /getfarmer [GET]
Traceback (most recent call last):
  File "/home/user/.local/lib/python3.6/site-packages/flask/app.py", line 1513, in full_dispatch_request
    rv = self.dispatch_request()
  File "/home/user/.local/lib/python3.6/site-packages/flask/app.py", line 1499, in dispatch_request
    return self.ensure_sync(self.view_functions[rule.endpoint])(**req.view_args)
  File "/home/user/.local/lib/python3.6/site-packages/flask_restful/__init__.py", line 467, in wrapper
    resp = resource(*args, **kwargs)
  File "/home/user/.local/lib/python3.6/site-packages/flask/views.py", line 83, in view
    return self.dispatch_request(*args, **kwargs)
  File "/home/user/.local/lib/python3.6/site-packages/flask_restful/__init__.py", line 582, in dispatch_request
    resp = meth(*args, **kwargs)
  File "/home/user/agrostar-workspace/farmerservice_flask/farmerservice/handler/farmerHandler.py", line 22, in get
    request_data = self.get
  File "/home/user/agrostar-workspace/farmerservice_flask/farmerservice/views/farmerController.py", line 89, in get_farmer
    phone_number = request_param.get("phone_no")
AttributeError: 'function' object has no attribute 'get'
[2021-06-17 15:59:15,992] ERROR in app: Exception on /shippingAddress [GET]
Traceback (most recent call last):
  File "/home/user/.local/lib/python3.6/site-packages/flask/app.py", line 1513, in full_dispatch_request
    rv = self.dispatch_request()
  File "/home/user/.local/lib/python3.6/site-packages/flask/app.py", line 1499, in dispatch_request
    return self.ensure_sync(self.view_functions[rule.endpoint])(**req.view_args)
  File "/home/user/.local/lib/python3.6/site-packages/flask_restful/__init__.py", line 467, in wrapper
    resp = resource(*args, **kwargs)
  File "/home/user/.local/lib/python3.6/site-packages/flask/views.py", line 83, in view
    return self.dispatch_request(*args, **kwargs)
  File "/home/user/.local/lib/python3.6/site-packages/flask_restful/__init__.py", line 582, in dispatch_request
    resp = meth(*args, **kwargs)
  File "/home/user/agrostar-workspace/farmerservice_flask/farmerservice/handler/shippingAddressHandler.py", line 14, in get
    resp = get_shipping_address(request_data)
  File "/home/user/agrostar-workspace/farmerservice_flask/farmerservice/views/shippingController.py", line 37, in get_shipping_address
    #get the farmer object
AttributeError: 'function' object has no attribute 'get'
[2021-06-17 16:01:47,557] ERROR in app: Exception on /getfarmer [GET]
Traceback (most recent call last):
  File "/home/user/.local/lib/python3.6/site-packages/flask/app.py", line 1513, in full_dispatch_request
    rv = self.dispatch_request()
  File "/home/user/.local/lib/python3.6/site-packages/flask/app.py", line 1499, in dispatch_request
    return self.ensure_sync(self.view_functions[rule.endpoint])(**req.view_args)
  File "/home/user/.local/lib/python3.6/site-packages/flask_restful/__init__.py", line 467, in wrapper
    resp = resource(*args, **kwargs)
  File "/home/user/.local/lib/python3.6/site-packages/flask/views.py", line 83, in view
    return self.dispatch_request(*args, **kwargs)
  File "/home/user/.local/lib/python3.6/site-packages/flask_restful/__init__.py", line 582, in dispatch_request
    resp = meth(*args, **kwargs)
  File "/home/user/agrostar-workspace/farmerservice_flask/farmerservice/handler/farmerHandler.py", line 22, in get
    resp = get_farmer(request_data)
  File "/home/user/agrostar-workspace/farmerservice_flask/farmerservice/views/farmerController.py", line 89, in get_farmer
    phone_number = request_param.get("phone_no")
AttributeError: 'function' object has no attribute 'get'
[2021-06-17 16:05:50,452] ERROR in app: Exception on /getfarmer [GET]
Traceback (most recent call last):
  File "/home/user/.local/lib/python3.6/site-packages/flask/app.py", line 1513, in full_dispatch_request
    rv = self.dispatch_request()
  File "/home/user/.local/lib/python3.6/site-packages/flask/app.py", line 1499, in dispatch_request
    return self.ensure_sync(self.view_functions[rule.endpoint])(**req.view_args)
  File "/home/user/.local/lib/python3.6/site-packages/flask_restful/__init__.py", line 467, in wrapper
    resp = resource(*args, **kwargs)
  File "/home/user/.local/lib/python3.6/site-packages/flask/views.py", line 83, in view
    return self.dispatch_request(*args, **kwargs)
  File "/home/user/.local/lib/python3.6/site-packages/flask_restful/__init__.py", line 582, in dispatch_request
    resp = meth(*args, **kwargs)
  File "/home/user/agrostar-workspace/farmerservice_flask/farmerservice/handler/farmerHandler.py", line 22, in get
    resp = get_farmer(request_data)
  File "/home/user/agrostar-workspace/farmerservice_flask/farmerservice/views/farmerController.py", line 89, in get_farmer
    phone_number = request_param.get("phone_no")
AttributeError: 'function' object has no attribute 'get'
[2021-06-17 16:07:42,285] ERROR in app: Exception on /getfarmer [GET]
Traceback (most recent call last):
  File "/home/user/.local/lib/python3.6/site-packages/flask/app.py", line 1513, in full_dispatch_request
    rv = self.dispatch_request()
  File "/home/user/.local/lib/python3.6/site-packages/flask/app.py", line 1499, in dispatch_request
    return self.ensure_sync(self.view_functions[rule.endpoint])(**req.view_args)
  File "/home/user/.local/lib/python3.6/site-packages/flask_restful/__init__.py", line 467, in wrapper
    resp = resource(*args, **kwargs)
  File "/home/user/.local/lib/python3.6/site-packages/flask/views.py", line 83, in view
    return self.dispatch_request(*args, **kwargs)
  File "/home/user/.local/lib/python3.6/site-packages/flask_restful/__init__.py", line 582, in dispatch_request
    resp = meth(*args, **kwargs)
  File "/home/user/agrostar-workspace/farmerservice_flask/farmerservice/handler/farmerHandler.py", line 22, in get
    resp = get_farmer(request_data)
  File "/home/user/agrostar-workspace/farmerservice_flask/farmerservice/views/farmerController.py", line 89, in get_farmer
    phone_number = request_param.get("phone_no")
AttributeError: 'function' object has no attribute 'get'
[2021-06-17 16:15:26,014] ERROR in app: Exception on /getfarmer [GET]
Traceback (most recent call last):
  File "/home/user/.local/lib/python3.6/site-packages/flask/app.py", line 1513, in full_dispatch_request
    rv = self.dispatch_request()
  File "/home/user/.local/lib/python3.6/site-packages/flask/app.py", line 1499, in dispatch_request
    return self.ensure_sync(self.view_functions[rule.endpoint])(**req.view_args)
  File "/home/user/.local/lib/python3.6/site-packages/flask_restful/__init__.py", line 467, in wrapper
    resp = resource(*args, **kwargs)
  File "/home/user/.local/lib/python3.6/site-packages/flask/views.py", line 83, in view
    return self.dispatch_request(*args, **kwargs)
  File "/home/user/.local/lib/python3.6/site-packages/flask_restful/__init__.py", line 582, in dispatch_request
    resp = meth(*args, **kwargs)
  File "/home/user/agrostar-workspace/farmerservice_flask/farmerservice/handler/farmerHandler.py", line 22, in get
    resp = get_farmer(request_data)
  File "/home/user/agrostar-workspace/farmerservice_flask/farmerservice/views/farmerController.py", line 89, in get_farmer
    phone_number = request_param.get("phone_no")
AttributeError: 'function' object has no attribute 'get'
[2021-06-17 16:16:00,227] ERROR in app: Exception on /getfarmer [GET]
Traceback (most recent call last):
  File "/home/user/.local/lib/python3.6/site-packages/flask/app.py", line 1513, in full_dispatch_request
    rv = self.dispatch_request()
  File "/home/user/.local/lib/python3.6/site-packages/flask/app.py", line 1499, in dispatch_request
    return self.ensure_sync(self.view_functions[rule.endpoint])(**req.view_args)
  File "/home/user/.local/lib/python3.6/site-packages/flask_restful/__init__.py", line 467, in wrapper
    resp = resource(*args, **kwargs)
  File "/home/user/.local/lib/python3.6/site-packages/flask/views.py", line 83, in view
    return self.dispatch_request(*args, **kwargs)
  File "/home/user/.local/lib/python3.6/site-packages/flask_restful/__init__.py", line 582, in dispatch_request
    resp = meth(*args, **kwargs)
  File "/home/user/agrostar-workspace/farmerservice_flask/farmerservice/handler/farmerHandler.py", line 22, in get
    resp = get_farmer(request_data)
  File "/home/user/agrostar-workspace/farmerservice_flask/farmerservice/views/farmerController.py", line 89, in get_farmer
    phone_number = request_param.get("phone_no")
AttributeError: 'function' object has no attribute 'get'
[2021-06-17 16:18:03,691] ERROR in app: Exception on /getfarmer [GET]
Traceback (most recent call last):
  File "/home/user/.local/lib/python3.6/site-packages/flask/app.py", line 1513, in full_dispatch_request
    rv = self.dispatch_request()
  File "/home/user/.local/lib/python3.6/site-packages/flask/app.py", line 1499, in dispatch_request
    return self.ensure_sync(self.view_functions[rule.endpoint])(**req.view_args)
  File "/home/user/.local/lib/python3.6/site-packages/flask_restful/__init__.py", line 467, in wrapper
    resp = resource(*args, **kwargs)
  File "/home/user/.local/lib/python3.6/site-packages/flask/views.py", line 83, in view
    return self.dispatch_request(*args, **kwargs)
  File "/home/user/.local/lib/python3.6/site-packages/flask_restful/__init__.py", line 582, in dispatch_request
    resp = meth(*args, **kwargs)
  File "/home/user/agrostar-workspace/farmerservice_flask/farmerservice/handler/farmerHandler.py", line 22, in get
    resp = get_farmer(request_data)
  File "/home/user/agrostar-workspace/farmerservice_flask/farmerservice/views/farmerController.py", line 89, in get_farmer
    phone_number = request_param.get("phone_no")
AttributeError: 'function' object has no attribute 'get'
[2021-06-17 16:18:16,141] ERROR in app: Exception on /farmer [POST]
Traceback (most recent call last):
  File "/home/user/.local/lib/python3.6/site-packages/flask/app.py", line 1513, in full_dispatch_request
    rv = self.dispatch_request()
  File "/home/user/.local/lib/python3.6/site-packages/flask/app.py", line 1499, in dispatch_request
    return self.ensure_sync(self.view_functions[rule.endpoint])(**req.view_args)
  File "/home/user/.local/lib/python3.6/site-packages/flask_restful/__init__.py", line 467, in wrapper
    resp = resource(*args, **kwargs)
  File "/home/user/.local/lib/python3.6/site-packages/flask/views.py", line 83, in view
    return self.dispatch_request(*args, **kwargs)
  File "/home/user/.local/lib/python3.6/site-packages/flask_restful/__init__.py", line 582, in dispatch_request
    resp = meth(*args, **kwargs)
  File "/home/user/agrostar-workspace/farmerservice_flask/farmerservice/handler/farmerHandler.py", line 8, in post
    resp = create_farmer(request_data)
AttributeError: 'FarmerHandler' object has no attribute 'json'
[2021-06-17 16:18:19,626] ERROR in app: Exception on /shippingAddress [GET]
Traceback (most recent call last):
  File "/home/user/.local/lib/python3.6/site-packages/flask/app.py", line 1513, in full_dispatch_request
    rv = self.dispatch_request()
  File "/home/user/.local/lib/python3.6/site-packages/flask/app.py", line 1499, in dispatch_request
    return self.ensure_sync(self.view_functions[rule.endpoint])(**req.view_args)
  File "/home/user/.local/lib/python3.6/site-packages/flask_restful/__init__.py", line 467, in wrapper
    resp = resource(*args, **kwargs)
  File "/home/user/.local/lib/python3.6/site-packages/flask/views.py", line 83, in view
    return self.dispatch_request(*args, **kwargs)
  File "/home/user/.local/lib/python3.6/site-packages/flask_restful/__init__.py", line 582, in dispatch_request
    resp = meth(*args, **kwargs)
  File "/home/user/agrostar-workspace/farmerservice_flask/farmerservice/handler/shippingAddressHandler.py", line 14, in get
    resp = get_shipping_address(request_data)
  File "/home/user/agrostar-workspace/farmerservice_flask/farmerservice/views/shippingController.py", line 37, in get_shipping_address
    #get the farmer object
AttributeError: 'function' object has no attribute 'get'
[2021-06-17 21:50:28 +0530] [19298] [INFO] Handling signal: term
[2021-06-17 16:20:28 +0000] [19301] [INFO] Worker exiting (pid: 19301)
[2021-06-17 21:50:28 +0530] [19298] [INFO] Shutting down: Master
[2021-06-18 13:00:13 +0530] [27402] [INFO] Starting gunicorn 20.1.0
[2021-06-18 13:00:13 +0530] [27402] [INFO] Listening at: http://127.0.0.1:8001 (27402)
[2021-06-18 13:00:13 +0530] [27402] [INFO] Using worker: sync
[2021-06-18 13:00:13 +0530] [27405] [INFO] Booting worker with pid: 27405
[2021-06-18 13:00:13 +0530] [27405] [ERROR] Exception in worker process
Traceback (most recent call last):
  File "/home/user/.local/lib/python3.6/site-packages/gunicorn/arbiter.py", line 589, in spawn_worker
    worker.init_process()
  File "/home/user/.local/lib/python3.6/site-packages/gunicorn/workers/base.py", line 134, in init_process
    self.load_wsgi()
  File "/home/user/.local/lib/python3.6/site-packages/gunicorn/workers/base.py", line 146, in load_wsgi
    self.wsgi = self.app.wsgi()
  File "/home/user/.local/lib/python3.6/site-packages/gunicorn/app/base.py", line 67, in wsgi
    self.callable = self.load()
  File "/home/user/.local/lib/python3.6/site-packages/gunicorn/app/wsgiapp.py", line 58, in load
    return self.load_wsgiapp()
  File "/home/user/.local/lib/python3.6/site-packages/gunicorn/app/wsgiapp.py", line 48, in load_wsgiapp
    return util.import_app(self.app_uri)
  File "/home/user/.local/lib/python3.6/site-packages/gunicorn/util.py", line 359, in import_app
    mod = importlib.import_module(module)
  File "/usr/lib/python3.6/importlib/__init__.py", line 126, in import_module
    return _bootstrap._gcd_import(name[level:], package, level)
  File "<frozen importlib._bootstrap>", line 994, in _gcd_import
  File "<frozen importlib._bootstrap>", line 971, in _find_and_load
  File "<frozen importlib._bootstrap>", line 953, in _find_and_load_unlocked
ModuleNotFoundError: No module named 'service'
[2021-06-18 13:00:13 +0530] [27405] [INFO] Worker exiting (pid: 27405)
[2021-06-18 13:00:13 +0530] [27402] [INFO] Shutting down: Master
[2021-06-18 13:00:13 +0530] [27402] [INFO] Reason: Worker failed to boot.
[2021-06-18 13:00:15 +0530] [27406] [INFO] Starting gunicorn 20.1.0
[2021-06-18 13:00:15 +0530] [27406] [INFO] Listening at: http://127.0.0.1:8001 (27406)
[2021-06-18 13:00:15 +0530] [27406] [INFO] Using worker: sync
[2021-06-18 13:00:15 +0530] [27409] [INFO] Booting worker with pid: 27409
[2021-06-18 13:00:15 +0530] [27409] [ERROR] Exception in worker process
Traceback (most recent call last):
  File "/home/user/.local/lib/python3.6/site-packages/gunicorn/arbiter.py", line 589, in spawn_worker
    worker.init_process()
  File "/home/user/.local/lib/python3.6/site-packages/gunicorn/workers/base.py", line 134, in init_process
    self.load_wsgi()
  File "/home/user/.local/lib/python3.6/site-packages/gunicorn/workers/base.py", line 146, in load_wsgi
    self.wsgi = self.app.wsgi()
  File "/home/user/.local/lib/python3.6/site-packages/gunicorn/app/base.py", line 67, in wsgi
    self.callable = self.load()
  File "/home/user/.local/lib/python3.6/site-packages/gunicorn/app/wsgiapp.py", line 58, in load
    return self.load_wsgiapp()
  File "/home/user/.local/lib/python3.6/site-packages/gunicorn/app/wsgiapp.py", line 48, in load_wsgiapp
    return util.import_app(self.app_uri)
  File "/home/user/.local/lib/python3.6/site-packages/gunicorn/util.py", line 359, in import_app
    mod = importlib.import_module(module)
  File "/usr/lib/python3.6/importlib/__init__.py", line 126, in import_module
    return _bootstrap._gcd_import(name[level:], package, level)
  File "<frozen importlib._bootstrap>", line 994, in _gcd_import
  File "<frozen importlib._bootstrap>", line 971, in _find_and_load
  File "<frozen importlib._bootstrap>", line 953, in _find_and_load_unlocked
ModuleNotFoundError: No module named 'service'
[2021-06-18 13:00:15 +0530] [27409] [INFO] Worker exiting (pid: 27409)
[2021-06-18 13:00:15 +0530] [27406] [INFO] Shutting down: Master
[2021-06-18 13:00:15 +0530] [27406] [INFO] Reason: Worker failed to boot.
[2021-06-18 13:00:17 +0530] [27410] [INFO] Starting gunicorn 20.1.0
[2021-06-18 13:00:17 +0530] [27410] [INFO] Listening at: http://127.0.0.1:8001 (27410)
[2021-06-18 13:00:17 +0530] [27410] [INFO] Using worker: sync
[2021-06-18 13:00:17 +0530] [27413] [INFO] Booting worker with pid: 27413
[2021-06-18 13:00:17 +0530] [27413] [ERROR] Exception in worker process
Traceback (most recent call last):
  File "/home/user/.local/lib/python3.6/site-packages/gunicorn/arbiter.py", line 589, in spawn_worker
    worker.init_process()
  File "/home/user/.local/lib/python3.6/site-packages/gunicorn/workers/base.py", line 134, in init_process
    self.load_wsgi()
  File "/home/user/.local/lib/python3.6/site-packages/gunicorn/workers/base.py", line 146, in load_wsgi
    self.wsgi = self.app.wsgi()
  File "/home/user/.local/lib/python3.6/site-packages/gunicorn/app/base.py", line 67, in wsgi
    self.callable = self.load()
  File "/home/user/.local/lib/python3.6/site-packages/gunicorn/app/wsgiapp.py", line 58, in load
    return self.load_wsgiapp()
  File "/home/user/.local/lib/python3.6/site-packages/gunicorn/app/wsgiapp.py", line 48, in load_wsgiapp
    return util.import_app(self.app_uri)
  File "/home/user/.local/lib/python3.6/site-packages/gunicorn/util.py", line 359, in import_app
    mod = importlib.import_module(module)
  File "/usr/lib/python3.6/importlib/__init__.py", line 126, in import_module
    return _bootstrap._gcd_import(name[level:], package, level)
  File "<frozen importlib._bootstrap>", line 994, in _gcd_import
  File "<frozen importlib._bootstrap>", line 971, in _find_and_load
  File "<frozen importlib._bootstrap>", line 953, in _find_and_load_unlocked
ModuleNotFoundError: No module named 'service'
[2021-06-18 13:00:17 +0530] [27413] [INFO] Worker exiting (pid: 27413)
[2021-06-18 13:00:17 +0530] [27410] [INFO] Shutting down: Master
[2021-06-18 13:00:17 +0530] [27410] [INFO] Reason: Worker failed to boot.
[2021-06-18 13:00:20 +0530] [27414] [INFO] Starting gunicorn 20.1.0
[2021-06-18 13:00:20 +0530] [27414] [INFO] Listening at: http://127.0.0.1:8001 (27414)
[2021-06-18 13:00:20 +0530] [27414] [INFO] Using worker: sync
[2021-06-18 13:00:20 +0530] [27417] [INFO] Booting worker with pid: 27417
[2021-06-18 13:00:20 +0530] [27417] [ERROR] Exception in worker process
Traceback (most recent call last):
  File "/home/user/.local/lib/python3.6/site-packages/gunicorn/arbiter.py", line 589, in spawn_worker
    worker.init_process()
  File "/home/user/.local/lib/python3.6/site-packages/gunicorn/workers/base.py", line 134, in init_process
    self.load_wsgi()
  File "/home/user/.local/lib/python3.6/site-packages/gunicorn/workers/base.py", line 146, in load_wsgi
    self.wsgi = self.app.wsgi()
  File "/home/user/.local/lib/python3.6/site-packages/gunicorn/app/base.py", line 67, in wsgi
    self.callable = self.load()
  File "/home/user/.local/lib/python3.6/site-packages/gunicorn/app/wsgiapp.py", line 58, in load
    return self.load_wsgiapp()
  File "/home/user/.local/lib/python3.6/site-packages/gunicorn/app/wsgiapp.py", line 48, in load_wsgiapp
    return util.import_app(self.app_uri)
  File "/home/user/.local/lib/python3.6/site-packages/gunicorn/util.py", line 359, in import_app
    mod = importlib.import_module(module)
  File "/usr/lib/python3.6/importlib/__init__.py", line 126, in import_module
    return _bootstrap._gcd_import(name[level:], package, level)
  File "<frozen importlib._bootstrap>", line 994, in _gcd_import
  File "<frozen importlib._bootstrap>", line 971, in _find_and_load
  File "<frozen importlib._bootstrap>", line 953, in _find_and_load_unlocked
ModuleNotFoundError: No module named 'service'
[2021-06-18 13:00:20 +0530] [27417] [INFO] Worker exiting (pid: 27417)
[2021-06-18 13:00:20 +0530] [27414] [INFO] Shutting down: Master
[2021-06-18 13:00:20 +0530] [27414] [INFO] Reason: Worker failed to boot.
[2021-06-18 15:22:14 +0530] [29593] [INFO] Starting gunicorn 20.1.0
[2021-06-18 15:22:14 +0530] [29593] [INFO] Listening at: http://127.0.0.1:8001 (29593)
[2021-06-18 15:22:14 +0530] [29593] [INFO] Using worker: sync
[2021-06-18 15:22:14 +0530] [29596] [INFO] Booting worker with pid: 29596
[2021-06-18 15:22:14 +0530] [29596] [ERROR] Exception in worker process
Traceback (most recent call last):
  File "/home/user/.local/lib/python3.6/site-packages/gunicorn/arbiter.py", line 589, in spawn_worker
    worker.init_process()
  File "/home/user/.local/lib/python3.6/site-packages/gunicorn/workers/base.py", line 134, in init_process
    self.load_wsgi()
  File "/home/user/.local/lib/python3.6/site-packages/gunicorn/workers/base.py", line 146, in load_wsgi
    self.wsgi = self.app.wsgi()
  File "/home/user/.local/lib/python3.6/site-packages/gunicorn/app/base.py", line 67, in wsgi
    self.callable = self.load()
  File "/home/user/.local/lib/python3.6/site-packages/gunicorn/app/wsgiapp.py", line 58, in load
    return self.load_wsgiapp()
  File "/home/user/.local/lib/python3.6/site-packages/gunicorn/app/wsgiapp.py", line 48, in load_wsgiapp
    return util.import_app(self.app_uri)
  File "/home/user/.local/lib/python3.6/site-packages/gunicorn/util.py", line 359, in import_app
    mod = importlib.import_module(module)
  File "/usr/lib/python3.6/importlib/__init__.py", line 126, in import_module
    return _bootstrap._gcd_import(name[level:], package, level)
  File "<frozen importlib._bootstrap>", line 994, in _gcd_import
  File "<frozen importlib._bootstrap>", line 971, in _find_and_load
  File "<frozen importlib._bootstrap>", line 953, in _find_and_load_unlocked
ModuleNotFoundError: No module named 'service'
[2021-06-18 15:22:14 +0530] [29596] [INFO] Worker exiting (pid: 29596)
[2021-06-18 15:22:14 +0530] [29593] [INFO] Shutting down: Master
[2021-06-18 15:22:14 +0530] [29593] [INFO] Reason: Worker failed to boot.
[2021-06-18 15:22:15 +0530] [29597] [INFO] Starting gunicorn 20.1.0
[2021-06-18 15:22:15 +0530] [29597] [INFO] Listening at: http://127.0.0.1:8001 (29597)
[2021-06-18 15:22:15 +0530] [29597] [INFO] Using worker: sync
[2021-06-18 15:22:15 +0530] [29600] [INFO] Booting worker with pid: 29600
[2021-06-18 15:22:15 +0530] [29600] [ERROR] Exception in worker process
Traceback (most recent call last):
  File "/home/user/.local/lib/python3.6/site-packages/gunicorn/arbiter.py", line 589, in spawn_worker
    worker.init_process()
  File "/home/user/.local/lib/python3.6/site-packages/gunicorn/workers/base.py", line 134, in init_process
    self.load_wsgi()
  File "/home/user/.local/lib/python3.6/site-packages/gunicorn/workers/base.py", line 146, in load_wsgi
    self.wsgi = self.app.wsgi()
  File "/home/user/.local/lib/python3.6/site-packages/gunicorn/app/base.py", line 67, in wsgi
    self.callable = self.load()
  File "/home/user/.local/lib/python3.6/site-packages/gunicorn/app/wsgiapp.py", line 58, in load
    return self.load_wsgiapp()
  File "/home/user/.local/lib/python3.6/site-packages/gunicorn/app/wsgiapp.py", line 48, in load_wsgiapp
    return util.import_app(self.app_uri)
  File "/home/user/.local/lib/python3.6/site-packages/gunicorn/util.py", line 359, in import_app
    mod = importlib.import_module(module)
  File "/usr/lib/python3.6/importlib/__init__.py", line 126, in import_module
    return _bootstrap._gcd_import(name[level:], package, level)
  File "<frozen importlib._bootstrap>", line 994, in _gcd_import
  File "<frozen importlib._bootstrap>", line 971, in _find_and_load
  File "<frozen importlib._bootstrap>", line 953, in _find_and_load_unlocked
ModuleNotFoundError: No module named 'service'
[2021-06-18 15:22:15 +0530] [29600] [INFO] Worker exiting (pid: 29600)
[2021-06-18 15:22:15 +0530] [29597] [INFO] Shutting down: Master
[2021-06-18 15:22:15 +0530] [29597] [INFO] Reason: Worker failed to boot.
[2021-06-18 15:22:17 +0530] [29601] [INFO] Starting gunicorn 20.1.0
[2021-06-18 15:22:17 +0530] [29601] [INFO] Listening at: http://127.0.0.1:8001 (29601)
[2021-06-18 15:22:17 +0530] [29601] [INFO] Using worker: sync
[2021-06-18 15:22:17 +0530] [29604] [INFO] Booting worker with pid: 29604
[2021-06-18 15:22:17 +0530] [29604] [ERROR] Exception in worker process
Traceback (most recent call last):
  File "/home/user/.local/lib/python3.6/site-packages/gunicorn/arbiter.py", line 589, in spawn_worker
    worker.init_process()
  File "/home/user/.local/lib/python3.6/site-packages/gunicorn/workers/base.py", line 134, in init_process
    self.load_wsgi()
  File "/home/user/.local/lib/python3.6/site-packages/gunicorn/workers/base.py", line 146, in load_wsgi
    self.wsgi = self.app.wsgi()
  File "/home/user/.local/lib/python3.6/site-packages/gunicorn/app/base.py", line 67, in wsgi
    self.callable = self.load()
  File "/home/user/.local/lib/python3.6/site-packages/gunicorn/app/wsgiapp.py", line 58, in load
    return self.load_wsgiapp()
  File "/home/user/.local/lib/python3.6/site-packages/gunicorn/app/wsgiapp.py", line 48, in load_wsgiapp
    return util.import_app(self.app_uri)
  File "/home/user/.local/lib/python3.6/site-packages/gunicorn/util.py", line 359, in import_app
    mod = importlib.import_module(module)
  File "/usr/lib/python3.6/importlib/__init__.py", line 126, in import_module
    return _bootstrap._gcd_import(name[level:], package, level)
  File "<frozen importlib._bootstrap>", line 994, in _gcd_import
  File "<frozen importlib._bootstrap>", line 971, in _find_and_load
  File "<frozen importlib._bootstrap>", line 953, in _find_and_load_unlocked
ModuleNotFoundError: No module named 'service'
[2021-06-18 15:22:17 +0530] [29604] [INFO] Worker exiting (pid: 29604)
[2021-06-18 15:22:17 +0530] [29601] [INFO] Shutting down: Master
[2021-06-18 15:22:17 +0530] [29601] [INFO] Reason: Worker failed to boot.
[2021-06-18 15:22:21 +0530] [29606] [INFO] Starting gunicorn 20.1.0
[2021-06-18 15:22:21 +0530] [29606] [INFO] Listening at: http://127.0.0.1:8001 (29606)
[2021-06-18 15:22:21 +0530] [29606] [INFO] Using worker: sync
[2021-06-18 15:22:21 +0530] [29609] [INFO] Booting worker with pid: 29609
[2021-06-18 15:22:21 +0530] [29609] [ERROR] Exception in worker process
Traceback (most recent call last):
  File "/home/user/.local/lib/python3.6/site-packages/gunicorn/arbiter.py", line 589, in spawn_worker
    worker.init_process()
  File "/home/user/.local/lib/python3.6/site-packages/gunicorn/workers/base.py", line 134, in init_process
    self.load_wsgi()
  File "/home/user/.local/lib/python3.6/site-packages/gunicorn/workers/base.py", line 146, in load_wsgi
    self.wsgi = self.app.wsgi()
  File "/home/user/.local/lib/python3.6/site-packages/gunicorn/app/base.py", line 67, in wsgi
    self.callable = self.load()
  File "/home/user/.local/lib/python3.6/site-packages/gunicorn/app/wsgiapp.py", line 58, in load
    return self.load_wsgiapp()
  File "/home/user/.local/lib/python3.6/site-packages/gunicorn/app/wsgiapp.py", line 48, in load_wsgiapp
    return util.import_app(self.app_uri)
  File "/home/user/.local/lib/python3.6/site-packages/gunicorn/util.py", line 359, in import_app
    mod = importlib.import_module(module)
  File "/usr/lib/python3.6/importlib/__init__.py", line 126, in import_module
    return _bootstrap._gcd_import(name[level:], package, level)
  File "<frozen importlib._bootstrap>", line 994, in _gcd_import
  File "<frozen importlib._bootstrap>", line 971, in _find_and_load
  File "<frozen importlib._bootstrap>", line 953, in _find_and_load_unlocked
ModuleNotFoundError: No module named 'service'
[2021-06-18 15:22:21 +0530] [29609] [INFO] Worker exiting (pid: 29609)
[2021-06-18 15:22:21 +0530] [29606] [INFO] Shutting down: Master
[2021-06-18 15:22:21 +0530] [29606] [INFO] Reason: Worker failed to boot.
[2021-06-18 15:23:22 +0530] [29748] [INFO] Starting gunicorn 20.1.0
[2021-06-18 15:23:22 +0530] [29748] [INFO] Listening at: http://127.0.0.1:8001 (29748)
[2021-06-18 15:23:22 +0530] [29748] [INFO] Using worker: sync
[2021-06-18 15:23:22 +0530] [29751] [INFO] Booting worker with pid: 29751
[2021-06-18 15:23:22 +0530] [29751] [ERROR] Exception in worker process
Traceback (most recent call last):
  File "/home/user/.local/lib/python3.6/site-packages/gunicorn/arbiter.py", line 589, in spawn_worker
    worker.init_process()
  File "/home/user/.local/lib/python3.6/site-packages/gunicorn/workers/base.py", line 134, in init_process
    self.load_wsgi()
  File "/home/user/.local/lib/python3.6/site-packages/gunicorn/workers/base.py", line 146, in load_wsgi
    self.wsgi = self.app.wsgi()
  File "/home/user/.local/lib/python3.6/site-packages/gunicorn/app/base.py", line 67, in wsgi
    self.callable = self.load()
  File "/home/user/.local/lib/python3.6/site-packages/gunicorn/app/wsgiapp.py", line 58, in load
    return self.load_wsgiapp()
  File "/home/user/.local/lib/python3.6/site-packages/gunicorn/app/wsgiapp.py", line 48, in load_wsgiapp
    return util.import_app(self.app_uri)
  File "/home/user/.local/lib/python3.6/site-packages/gunicorn/util.py", line 359, in import_app
    mod = importlib.import_module(module)
  File "/usr/lib/python3.6/importlib/__init__.py", line 126, in import_module
    return _bootstrap._gcd_import(name[level:], package, level)
  File "<frozen importlib._bootstrap>", line 994, in _gcd_import
  File "<frozen importlib._bootstrap>", line 971, in _find_and_load
  File "<frozen importlib._bootstrap>", line 953, in _find_and_load_unlocked
ModuleNotFoundError: No module named 'service'
[2021-06-18 15:23:22 +0530] [29751] [INFO] Worker exiting (pid: 29751)
[2021-06-18 15:23:22 +0530] [29748] [INFO] Shutting down: Master
[2021-06-18 15:23:22 +0530] [29748] [INFO] Reason: Worker failed to boot.
[2021-06-18 15:23:23 +0530] [29752] [INFO] Starting gunicorn 20.1.0
[2021-06-18 15:23:23 +0530] [29752] [INFO] Listening at: http://127.0.0.1:8001 (29752)
[2021-06-18 15:23:23 +0530] [29752] [INFO] Using worker: sync
[2021-06-18 15:23:23 +0530] [29755] [INFO] Booting worker with pid: 29755
[2021-06-18 15:23:23 +0530] [29755] [ERROR] Exception in worker process
Traceback (most recent call last):
  File "/home/user/.local/lib/python3.6/site-packages/gunicorn/arbiter.py", line 589, in spawn_worker
    worker.init_process()
  File "/home/user/.local/lib/python3.6/site-packages/gunicorn/workers/base.py", line 134, in init_process
    self.load_wsgi()
  File "/home/user/.local/lib/python3.6/site-packages/gunicorn/workers/base.py", line 146, in load_wsgi
    self.wsgi = self.app.wsgi()
  File "/home/user/.local/lib/python3.6/site-packages/gunicorn/app/base.py", line 67, in wsgi
    self.callable = self.load()
  File "/home/user/.local/lib/python3.6/site-packages/gunicorn/app/wsgiapp.py", line 58, in load
    return self.load_wsgiapp()
  File "/home/user/.local/lib/python3.6/site-packages/gunicorn/app/wsgiapp.py", line 48, in load_wsgiapp
    return util.import_app(self.app_uri)
  File "/home/user/.local/lib/python3.6/site-packages/gunicorn/util.py", line 359, in import_app
    mod = importlib.import_module(module)
  File "/usr/lib/python3.6/importlib/__init__.py", line 126, in import_module
    return _bootstrap._gcd_import(name[level:], package, level)
  File "<frozen importlib._bootstrap>", line 994, in _gcd_import
  File "<frozen importlib._bootstrap>", line 971, in _find_and_load
  File "<frozen importlib._bootstrap>", line 953, in _find_and_load_unlocked
ModuleNotFoundError: No module named 'service'
[2021-06-18 15:23:23 +0530] [29755] [INFO] Worker exiting (pid: 29755)
[2021-06-18 15:23:23 +0530] [29752] [INFO] Shutting down: Master
[2021-06-18 15:23:23 +0530] [29752] [INFO] Reason: Worker failed to boot.
[2021-06-18 15:23:26 +0530] [29756] [INFO] Starting gunicorn 20.1.0
[2021-06-18 15:23:26 +0530] [29756] [INFO] Listening at: http://127.0.0.1:8001 (29756)
[2021-06-18 15:23:26 +0530] [29756] [INFO] Using worker: sync
[2021-06-18 15:23:26 +0530] [29759] [INFO] Booting worker with pid: 29759
[2021-06-18 15:23:26 +0530] [29759] [ERROR] Exception in worker process
Traceback (most recent call last):
  File "/home/user/.local/lib/python3.6/site-packages/gunicorn/arbiter.py", line 589, in spawn_worker
    worker.init_process()
  File "/home/user/.local/lib/python3.6/site-packages/gunicorn/workers/base.py", line 134, in init_process
    self.load_wsgi()
  File "/home/user/.local/lib/python3.6/site-packages/gunicorn/workers/base.py", line 146, in load_wsgi
    self.wsgi = self.app.wsgi()
  File "/home/user/.local/lib/python3.6/site-packages/gunicorn/app/base.py", line 67, in wsgi
    self.callable = self.load()
  File "/home/user/.local/lib/python3.6/site-packages/gunicorn/app/wsgiapp.py", line 58, in load
    return self.load_wsgiapp()
  File "/home/user/.local/lib/python3.6/site-packages/gunicorn/app/wsgiapp.py", line 48, in load_wsgiapp
    return util.import_app(self.app_uri)
  File "/home/user/.local/lib/python3.6/site-packages/gunicorn/util.py", line 359, in import_app
    mod = importlib.import_module(module)
  File "/usr/lib/python3.6/importlib/__init__.py", line 126, in import_module
    return _bootstrap._gcd_import(name[level:], package, level)
  File "<frozen importlib._bootstrap>", line 994, in _gcd_import
  File "<frozen importlib._bootstrap>", line 971, in _find_and_load
  File "<frozen importlib._bootstrap>", line 953, in _find_and_load_unlocked
ModuleNotFoundError: No module named 'service'
[2021-06-18 15:23:26 +0530] [29759] [INFO] Worker exiting (pid: 29759)
[2021-06-18 15:23:26 +0530] [29756] [INFO] Shutting down: Master
[2021-06-18 15:23:26 +0530] [29756] [INFO] Reason: Worker failed to boot.
[2021-06-18 15:23:29 +0530] [29760] [INFO] Starting gunicorn 20.1.0
[2021-06-18 15:23:29 +0530] [29760] [INFO] Listening at: http://127.0.0.1:8001 (29760)
[2021-06-18 15:23:29 +0530] [29760] [INFO] Using worker: sync
[2021-06-18 15:23:29 +0530] [29763] [INFO] Booting worker with pid: 29763
[2021-06-18 15:23:29 +0530] [29763] [ERROR] Exception in worker process
Traceback (most recent call last):
  File "/home/user/.local/lib/python3.6/site-packages/gunicorn/arbiter.py", line 589, in spawn_worker
    worker.init_process()
  File "/home/user/.local/lib/python3.6/site-packages/gunicorn/workers/base.py", line 134, in init_process
    self.load_wsgi()
  File "/home/user/.local/lib/python3.6/site-packages/gunicorn/workers/base.py", line 146, in load_wsgi
    self.wsgi = self.app.wsgi()
  File "/home/user/.local/lib/python3.6/site-packages/gunicorn/app/base.py", line 67, in wsgi
    self.callable = self.load()
  File "/home/user/.local/lib/python3.6/site-packages/gunicorn/app/wsgiapp.py", line 58, in load
    return self.load_wsgiapp()
  File "/home/user/.local/lib/python3.6/site-packages/gunicorn/app/wsgiapp.py", line 48, in load_wsgiapp
    return util.import_app(self.app_uri)
  File "/home/user/.local/lib/python3.6/site-packages/gunicorn/util.py", line 359, in import_app
    mod = importlib.import_module(module)
  File "/usr/lib/python3.6/importlib/__init__.py", line 126, in import_module
    return _bootstrap._gcd_import(name[level:], package, level)
  File "<frozen importlib._bootstrap>", line 994, in _gcd_import
  File "<frozen importlib._bootstrap>", line 971, in _find_and_load
  File "<frozen importlib._bootstrap>", line 953, in _find_and_load_unlocked
ModuleNotFoundError: No module named 'service'
[2021-06-18 15:23:29 +0530] [29763] [INFO] Worker exiting (pid: 29763)
[2021-06-18 15:23:29 +0530] [29760] [INFO] Shutting down: Master
[2021-06-18 15:23:29 +0530] [29760] [INFO] Reason: Worker failed to boot.
[2021-06-18 15:23:44 +0530] [29765] [INFO] Starting gunicorn 20.1.0
[2021-06-18 15:23:44 +0530] [29765] [INFO] Listening at: http://127.0.0.1:8001 (29765)
[2021-06-18 15:23:44 +0530] [29765] [INFO] Using worker: sync
[2021-06-18 15:23:44 +0530] [29768] [INFO] Booting worker with pid: 29768
[2021-06-18 15:23:44 +0530] [29768] [ERROR] Exception in worker process
Traceback (most recent call last):
  File "/home/user/.local/lib/python3.6/site-packages/gunicorn/arbiter.py", line 589, in spawn_worker
    worker.init_process()
  File "/home/user/.local/lib/python3.6/site-packages/gunicorn/workers/base.py", line 134, in init_process
    self.load_wsgi()
  File "/home/user/.local/lib/python3.6/site-packages/gunicorn/workers/base.py", line 146, in load_wsgi
    self.wsgi = self.app.wsgi()
  File "/home/user/.local/lib/python3.6/site-packages/gunicorn/app/base.py", line 67, in wsgi
    self.callable = self.load()
  File "/home/user/.local/lib/python3.6/site-packages/gunicorn/app/wsgiapp.py", line 58, in load
    return self.load_wsgiapp()
  File "/home/user/.local/lib/python3.6/site-packages/gunicorn/app/wsgiapp.py", line 48, in load_wsgiapp
    return util.import_app(self.app_uri)
  File "/home/user/.local/lib/python3.6/site-packages/gunicorn/util.py", line 359, in import_app
    mod = importlib.import_module(module)
  File "/usr/lib/python3.6/importlib/__init__.py", line 126, in import_module
    return _bootstrap._gcd_import(name[level:], package, level)
  File "<frozen importlib._bootstrap>", line 994, in _gcd_import
  File "<frozen importlib._bootstrap>", line 971, in _find_and_load
  File "<frozen importlib._bootstrap>", line 953, in _find_and_load_unlocked
ModuleNotFoundError: No module named 'service'
[2021-06-18 15:23:44 +0530] [29768] [INFO] Worker exiting (pid: 29768)
[2021-06-18 15:23:44 +0530] [29765] [INFO] Shutting down: Master
[2021-06-18 15:23:44 +0530] [29765] [INFO] Reason: Worker failed to boot.
[2021-06-18 15:23:45 +0530] [29769] [INFO] Starting gunicorn 20.1.0
[2021-06-18 15:23:45 +0530] [29769] [INFO] Listening at: http://127.0.0.1:8001 (29769)
[2021-06-18 15:23:45 +0530] [29769] [INFO] Using worker: sync
[2021-06-18 15:23:45 +0530] [29772] [INFO] Booting worker with pid: 29772
[2021-06-18 15:23:45 +0530] [29772] [ERROR] Exception in worker process
Traceback (most recent call last):
  File "/home/user/.local/lib/python3.6/site-packages/gunicorn/arbiter.py", line 589, in spawn_worker
    worker.init_process()
  File "/home/user/.local/lib/python3.6/site-packages/gunicorn/workers/base.py", line 134, in init_process
    self.load_wsgi()
  File "/home/user/.local/lib/python3.6/site-packages/gunicorn/workers/base.py", line 146, in load_wsgi
    self.wsgi = self.app.wsgi()
  File "/home/user/.local/lib/python3.6/site-packages/gunicorn/app/base.py", line 67, in wsgi
    self.callable = self.load()
  File "/home/user/.local/lib/python3.6/site-packages/gunicorn/app/wsgiapp.py", line 58, in load
    return self.load_wsgiapp()
  File "/home/user/.local/lib/python3.6/site-packages/gunicorn/app/wsgiapp.py", line 48, in load_wsgiapp
    return util.import_app(self.app_uri)
  File "/home/user/.local/lib/python3.6/site-packages/gunicorn/util.py", line 359, in import_app
    mod = importlib.import_module(module)
  File "/usr/lib/python3.6/importlib/__init__.py", line 126, in import_module
    return _bootstrap._gcd_import(name[level:], package, level)
  File "<frozen importlib._bootstrap>", line 994, in _gcd_import
  File "<frozen importlib._bootstrap>", line 971, in _find_and_load
  File "<frozen importlib._bootstrap>", line 953, in _find_and_load_unlocked
ModuleNotFoundError: No module named 'service'
[2021-06-18 15:23:45 +0530] [29772] [INFO] Worker exiting (pid: 29772)
[2021-06-18 15:23:45 +0530] [29769] [INFO] Shutting down: Master
[2021-06-18 15:23:45 +0530] [29769] [INFO] Reason: Worker failed to boot.
[2021-06-18 15:23:47 +0530] [29773] [INFO] Starting gunicorn 20.1.0
[2021-06-18 15:23:47 +0530] [29773] [INFO] Listening at: http://127.0.0.1:8001 (29773)
[2021-06-18 15:23:47 +0530] [29773] [INFO] Using worker: sync
[2021-06-18 15:23:47 +0530] [29776] [INFO] Booting worker with pid: 29776
[2021-06-18 15:23:47 +0530] [29776] [ERROR] Exception in worker process
Traceback (most recent call last):
  File "/home/user/.local/lib/python3.6/site-packages/gunicorn/arbiter.py", line 589, in spawn_worker
    worker.init_process()
  File "/home/user/.local/lib/python3.6/site-packages/gunicorn/workers/base.py", line 134, in init_process
    self.load_wsgi()
  File "/home/user/.local/lib/python3.6/site-packages/gunicorn/workers/base.py", line 146, in load_wsgi
    self.wsgi = self.app.wsgi()
  File "/home/user/.local/lib/python3.6/site-packages/gunicorn/app/base.py", line 67, in wsgi
    self.callable = self.load()
  File "/home/user/.local/lib/python3.6/site-packages/gunicorn/app/wsgiapp.py", line 58, in load
    return self.load_wsgiapp()
  File "/home/user/.local/lib/python3.6/site-packages/gunicorn/app/wsgiapp.py", line 48, in load_wsgiapp
    return util.import_app(self.app_uri)
  File "/home/user/.local/lib/python3.6/site-packages/gunicorn/util.py", line 359, in import_app
    mod = importlib.import_module(module)
  File "/usr/lib/python3.6/importlib/__init__.py", line 126, in import_module
    return _bootstrap._gcd_import(name[level:], package, level)
  File "<frozen importlib._bootstrap>", line 994, in _gcd_import
  File "<frozen importlib._bootstrap>", line 971, in _find_and_load
  File "<frozen importlib._bootstrap>", line 953, in _find_and_load_unlocked
ModuleNotFoundError: No module named 'service'
[2021-06-18 15:23:47 +0530] [29776] [INFO] Worker exiting (pid: 29776)
[2021-06-18 15:23:47 +0530] [29773] [INFO] Shutting down: Master
[2021-06-18 15:23:47 +0530] [29773] [INFO] Reason: Worker failed to boot.
[2021-06-18 15:23:50 +0530] [29778] [INFO] Starting gunicorn 20.1.0
[2021-06-18 15:23:50 +0530] [29778] [INFO] Listening at: http://127.0.0.1:8001 (29778)
[2021-06-18 15:23:50 +0530] [29778] [INFO] Using worker: sync
[2021-06-18 15:23:50 +0530] [29781] [INFO] Booting worker with pid: 29781
[2021-06-18 15:23:50 +0530] [29781] [ERROR] Exception in worker process
Traceback (most recent call last):
  File "/home/user/.local/lib/python3.6/site-packages/gunicorn/arbiter.py", line 589, in spawn_worker
    worker.init_process()
  File "/home/user/.local/lib/python3.6/site-packages/gunicorn/workers/base.py", line 134, in init_process
    self.load_wsgi()
  File "/home/user/.local/lib/python3.6/site-packages/gunicorn/workers/base.py", line 146, in load_wsgi
    self.wsgi = self.app.wsgi()
  File "/home/user/.local/lib/python3.6/site-packages/gunicorn/app/base.py", line 67, in wsgi
    self.callable = self.load()
  File "/home/user/.local/lib/python3.6/site-packages/gunicorn/app/wsgiapp.py", line 58, in load
    return self.load_wsgiapp()
  File "/home/user/.local/lib/python3.6/site-packages/gunicorn/app/wsgiapp.py", line 48, in load_wsgiapp
    return util.import_app(self.app_uri)
  File "/home/user/.local/lib/python3.6/site-packages/gunicorn/util.py", line 359, in import_app
    mod = importlib.import_module(module)
  File "/usr/lib/python3.6/importlib/__init__.py", line 126, in import_module
    return _bootstrap._gcd_import(name[level:], package, level)
  File "<frozen importlib._bootstrap>", line 994, in _gcd_import
  File "<frozen importlib._bootstrap>", line 971, in _find_and_load
  File "<frozen importlib._bootstrap>", line 953, in _find_and_load_unlocked
ModuleNotFoundError: No module named 'service'
[2021-06-18 15:23:50 +0530] [29781] [INFO] Worker exiting (pid: 29781)
[2021-06-18 15:23:50 +0530] [29778] [INFO] Shutting down: Master
[2021-06-18 15:23:50 +0530] [29778] [INFO] Reason: Worker failed to boot.
[2021-06-18 15:25:50 +0530] [29797] [INFO] Starting gunicorn 20.1.0
[2021-06-18 15:25:50 +0530] [29797] [INFO] Listening at: http://127.0.0.1:8001 (29797)
[2021-06-18 15:25:50 +0530] [29797] [INFO] Using worker: sync
[2021-06-18 15:25:50 +0530] [29800] [INFO] Booting worker with pid: 29800
[2021-06-18 15:25:50 +0530] [29800] [ERROR] Exception in worker process
Traceback (most recent call last):
  File "/home/user/.local/lib/python3.6/site-packages/gunicorn/arbiter.py", line 589, in spawn_worker
    worker.init_process()
  File "/home/user/.local/lib/python3.6/site-packages/gunicorn/workers/base.py", line 134, in init_process
    self.load_wsgi()
  File "/home/user/.local/lib/python3.6/site-packages/gunicorn/workers/base.py", line 146, in load_wsgi
    self.wsgi = self.app.wsgi()
  File "/home/user/.local/lib/python3.6/site-packages/gunicorn/app/base.py", line 67, in wsgi
    self.callable = self.load()
  File "/home/user/.local/lib/python3.6/site-packages/gunicorn/app/wsgiapp.py", line 58, in load
    return self.load_wsgiapp()
  File "/home/user/.local/lib/python3.6/site-packages/gunicorn/app/wsgiapp.py", line 48, in load_wsgiapp
    return util.import_app(self.app_uri)
  File "/home/user/.local/lib/python3.6/site-packages/gunicorn/util.py", line 359, in import_app
    mod = importlib.import_module(module)
  File "/usr/lib/python3.6/importlib/__init__.py", line 126, in import_module
    return _bootstrap._gcd_import(name[level:], package, level)
  File "<frozen importlib._bootstrap>", line 994, in _gcd_import
  File "<frozen importlib._bootstrap>", line 971, in _find_and_load
  File "<frozen importlib._bootstrap>", line 953, in _find_and_load_unlocked
ModuleNotFoundError: No module named 'service'
[2021-06-18 15:25:50 +0530] [29800] [INFO] Worker exiting (pid: 29800)
[2021-06-18 15:25:50 +0530] [29797] [INFO] Shutting down: Master
[2021-06-18 15:25:50 +0530] [29797] [INFO] Reason: Worker failed to boot.
[2021-06-18 15:25:55 +0530] [29803] [INFO] Starting gunicorn 20.1.0
[2021-06-18 15:25:55 +0530] [29803] [INFO] Listening at: http://127.0.0.1:8001 (29803)
[2021-06-18 15:25:55 +0530] [29803] [INFO] Using worker: sync
[2021-06-18 15:25:55 +0530] [29806] [INFO] Booting worker with pid: 29806
[2021-06-18 15:25:55 +0530] [29806] [ERROR] Exception in worker process
Traceback (most recent call last):
  File "/home/user/.local/lib/python3.6/site-packages/gunicorn/arbiter.py", line 589, in spawn_worker
    worker.init_process()
  File "/home/user/.local/lib/python3.6/site-packages/gunicorn/workers/base.py", line 134, in init_process
    self.load_wsgi()
  File "/home/user/.local/lib/python3.6/site-packages/gunicorn/workers/base.py", line 146, in load_wsgi
    self.wsgi = self.app.wsgi()
  File "/home/user/.local/lib/python3.6/site-packages/gunicorn/app/base.py", line 67, in wsgi
    self.callable = self.load()
  File "/home/user/.local/lib/python3.6/site-packages/gunicorn/app/wsgiapp.py", line 58, in load
    return self.load_wsgiapp()
  File "/home/user/.local/lib/python3.6/site-packages/gunicorn/app/wsgiapp.py", line 48, in load_wsgiapp
    return util.import_app(self.app_uri)
  File "/home/user/.local/lib/python3.6/site-packages/gunicorn/util.py", line 359, in import_app
    mod = importlib.import_module(module)
  File "/usr/lib/python3.6/importlib/__init__.py", line 126, in import_module
    return _bootstrap._gcd_import(name[level:], package, level)
  File "<frozen importlib._bootstrap>", line 994, in _gcd_import
  File "<frozen importlib._bootstrap>", line 971, in _find_and_load
  File "<frozen importlib._bootstrap>", line 953, in _find_and_load_unlocked
ModuleNotFoundError: No module named 'service'
[2021-06-18 15:25:55 +0530] [29806] [INFO] Worker exiting (pid: 29806)
[2021-06-18 15:25:55 +0530] [29803] [INFO] Shutting down: Master
[2021-06-18 15:25:55 +0530] [29803] [INFO] Reason: Worker failed to boot.
[2021-06-18 15:25:58 +0530] [29810] [INFO] Starting gunicorn 20.1.0
[2021-06-18 15:25:58 +0530] [29810] [INFO] Listening at: http://127.0.0.1:8001 (29810)
[2021-06-18 15:25:58 +0530] [29810] [INFO] Using worker: sync
[2021-06-18 15:25:58 +0530] [29813] [INFO] Booting worker with pid: 29813
[2021-06-18 15:25:58 +0530] [29813] [ERROR] Exception in worker process
Traceback (most recent call last):
  File "/home/user/.local/lib/python3.6/site-packages/gunicorn/arbiter.py", line 589, in spawn_worker
    worker.init_process()
  File "/home/user/.local/lib/python3.6/site-packages/gunicorn/workers/base.py", line 134, in init_process
    self.load_wsgi()
  File "/home/user/.local/lib/python3.6/site-packages/gunicorn/workers/base.py", line 146, in load_wsgi
    self.wsgi = self.app.wsgi()
  File "/home/user/.local/lib/python3.6/site-packages/gunicorn/app/base.py", line 67, in wsgi
    self.callable = self.load()
  File "/home/user/.local/lib/python3.6/site-packages/gunicorn/app/wsgiapp.py", line 58, in load
    return self.load_wsgiapp()
  File "/home/user/.local/lib/python3.6/site-packages/gunicorn/app/wsgiapp.py", line 48, in load_wsgiapp
    return util.import_app(self.app_uri)
  File "/home/user/.local/lib/python3.6/site-packages/gunicorn/util.py", line 359, in import_app
    mod = importlib.import_module(module)
  File "/usr/lib/python3.6/importlib/__init__.py", line 126, in import_module
    return _bootstrap._gcd_import(name[level:], package, level)
  File "<frozen importlib._bootstrap>", line 994, in _gcd_import
  File "<frozen importlib._bootstrap>", line 971, in _find_and_load
  File "<frozen importlib._bootstrap>", line 953, in _find_and_load_unlocked
ModuleNotFoundError: No module named 'service'
[2021-06-18 15:25:58 +0530] [29813] [INFO] Worker exiting (pid: 29813)
[2021-06-18 15:25:58 +0530] [29810] [INFO] Shutting down: Master
[2021-06-18 15:25:58 +0530] [29810] [INFO] Reason: Worker failed to boot.
[2021-06-18 15:26:02 +0530] [29816] [INFO] Starting gunicorn 20.1.0
[2021-06-18 15:26:02 +0530] [29816] [INFO] Listening at: http://127.0.0.1:8001 (29816)
[2021-06-18 15:26:02 +0530] [29816] [INFO] Using worker: sync
[2021-06-18 15:26:02 +0530] [29819] [INFO] Booting worker with pid: 29819
[2021-06-18 15:26:02 +0530] [29819] [ERROR] Exception in worker process
Traceback (most recent call last):
  File "/home/user/.local/lib/python3.6/site-packages/gunicorn/arbiter.py", line 589, in spawn_worker
    worker.init_process()
  File "/home/user/.local/lib/python3.6/site-packages/gunicorn/workers/base.py", line 134, in init_process
    self.load_wsgi()
  File "/home/user/.local/lib/python3.6/site-packages/gunicorn/workers/base.py", line 146, in load_wsgi
    self.wsgi = self.app.wsgi()
  File "/home/user/.local/lib/python3.6/site-packages/gunicorn/app/base.py", line 67, in wsgi
    self.callable = self.load()
  File "/home/user/.local/lib/python3.6/site-packages/gunicorn/app/wsgiapp.py", line 58, in load
    return self.load_wsgiapp()
  File "/home/user/.local/lib/python3.6/site-packages/gunicorn/app/wsgiapp.py", line 48, in load_wsgiapp
    return util.import_app(self.app_uri)
  File "/home/user/.local/lib/python3.6/site-packages/gunicorn/util.py", line 359, in import_app
    mod = importlib.import_module(module)
  File "/usr/lib/python3.6/importlib/__init__.py", line 126, in import_module
    return _bootstrap._gcd_import(name[level:], package, level)
  File "<frozen importlib._bootstrap>", line 994, in _gcd_import
  File "<frozen importlib._bootstrap>", line 971, in _find_and_load
  File "<frozen importlib._bootstrap>", line 953, in _find_and_load_unlocked
ModuleNotFoundError: No module named 'service'
[2021-06-18 15:26:02 +0530] [29819] [INFO] Worker exiting (pid: 29819)
[2021-06-18 15:26:02 +0530] [29816] [INFO] Shutting down: Master
[2021-06-18 15:26:02 +0530] [29816] [INFO] Reason: Worker failed to boot.
[2021-06-18 15:31:28 +0530] [29927] [INFO] Starting gunicorn 20.1.0
[2021-06-18 15:31:28 +0530] [29927] [INFO] Listening at: http://127.0.0.1:8001 (29927)
[2021-06-18 15:31:28 +0530] [29927] [INFO] Using worker: sync
[2021-06-18 15:31:28 +0530] [29930] [INFO] Booting worker with pid: 29930
[2021-06-18 15:31:28 +0530] [29930] [ERROR] Exception in worker process
Traceback (most recent call last):
  File "/home/user/.local/lib/python3.6/site-packages/gunicorn/arbiter.py", line 589, in spawn_worker
    worker.init_process()
  File "/home/user/.local/lib/python3.6/site-packages/gunicorn/workers/base.py", line 134, in init_process
    self.load_wsgi()
  File "/home/user/.local/lib/python3.6/site-packages/gunicorn/workers/base.py", line 146, in load_wsgi
    self.wsgi = self.app.wsgi()
  File "/home/user/.local/lib/python3.6/site-packages/gunicorn/app/base.py", line 67, in wsgi
    self.callable = self.load()
  File "/home/user/.local/lib/python3.6/site-packages/gunicorn/app/wsgiapp.py", line 58, in load
    return self.load_wsgiapp()
  File "/home/user/.local/lib/python3.6/site-packages/gunicorn/app/wsgiapp.py", line 48, in load_wsgiapp
    return util.import_app(self.app_uri)
  File "/home/user/.local/lib/python3.6/site-packages/gunicorn/util.py", line 359, in import_app
    mod = importlib.import_module(module)
  File "/usr/lib/python3.6/importlib/__init__.py", line 126, in import_module
    return _bootstrap._gcd_import(name[level:], package, level)
  File "<frozen importlib._bootstrap>", line 994, in _gcd_import
  File "<frozen importlib._bootstrap>", line 971, in _find_and_load
  File "<frozen importlib._bootstrap>", line 953, in _find_and_load_unlocked
ModuleNotFoundError: No module named 'service'
[2021-06-18 15:31:28 +0530] [29930] [INFO] Worker exiting (pid: 29930)
[2021-06-18 15:31:28 +0530] [29927] [INFO] Shutting down: Master
[2021-06-18 15:31:28 +0530] [29927] [INFO] Reason: Worker failed to boot.
[2021-06-18 15:31:29 +0530] [29931] [INFO] Starting gunicorn 20.1.0
[2021-06-18 15:31:29 +0530] [29931] [INFO] Listening at: http://127.0.0.1:8001 (29931)
[2021-06-18 15:31:29 +0530] [29931] [INFO] Using worker: sync
[2021-06-18 15:31:29 +0530] [29934] [INFO] Booting worker with pid: 29934
[2021-06-18 15:31:29 +0530] [29934] [ERROR] Exception in worker process
Traceback (most recent call last):
  File "/home/user/.local/lib/python3.6/site-packages/gunicorn/arbiter.py", line 589, in spawn_worker
    worker.init_process()
  File "/home/user/.local/lib/python3.6/site-packages/gunicorn/workers/base.py", line 134, in init_process
    self.load_wsgi()
  File "/home/user/.local/lib/python3.6/site-packages/gunicorn/workers/base.py", line 146, in load_wsgi
    self.wsgi = self.app.wsgi()
  File "/home/user/.local/lib/python3.6/site-packages/gunicorn/app/base.py", line 67, in wsgi
    self.callable = self.load()
  File "/home/user/.local/lib/python3.6/site-packages/gunicorn/app/wsgiapp.py", line 58, in load
    return self.load_wsgiapp()
  File "/home/user/.local/lib/python3.6/site-packages/gunicorn/app/wsgiapp.py", line 48, in load_wsgiapp
    return util.import_app(self.app_uri)
  File "/home/user/.local/lib/python3.6/site-packages/gunicorn/util.py", line 359, in import_app
    mod = importlib.import_module(module)
  File "/usr/lib/python3.6/importlib/__init__.py", line 126, in import_module
    return _bootstrap._gcd_import(name[level:], package, level)
  File "<frozen importlib._bootstrap>", line 994, in _gcd_import
  File "<frozen importlib._bootstrap>", line 971, in _find_and_load
  File "<frozen importlib._bootstrap>", line 953, in _find_and_load_unlocked
ModuleNotFoundError: No module named 'service'
[2021-06-18 15:31:29 +0530] [29934] [INFO] Worker exiting (pid: 29934)
[2021-06-18 15:31:29 +0530] [29931] [INFO] Shutting down: Master
[2021-06-18 15:31:29 +0530] [29931] [INFO] Reason: Worker failed to boot.
[2021-06-18 15:31:32 +0530] [29935] [INFO] Starting gunicorn 20.1.0
[2021-06-18 15:31:32 +0530] [29935] [INFO] Listening at: http://127.0.0.1:8001 (29935)
[2021-06-18 15:31:32 +0530] [29935] [INFO] Using worker: sync
[2021-06-18 15:31:32 +0530] [29938] [INFO] Booting worker with pid: 29938
[2021-06-18 15:31:32 +0530] [29938] [ERROR] Exception in worker process
Traceback (most recent call last):
  File "/home/user/.local/lib/python3.6/site-packages/gunicorn/arbiter.py", line 589, in spawn_worker
    worker.init_process()
  File "/home/user/.local/lib/python3.6/site-packages/gunicorn/workers/base.py", line 134, in init_process
    self.load_wsgi()
  File "/home/user/.local/lib/python3.6/site-packages/gunicorn/workers/base.py", line 146, in load_wsgi
    self.wsgi = self.app.wsgi()
  File "/home/user/.local/lib/python3.6/site-packages/gunicorn/app/base.py", line 67, in wsgi
    self.callable = self.load()
  File "/home/user/.local/lib/python3.6/site-packages/gunicorn/app/wsgiapp.py", line 58, in load
    return self.load_wsgiapp()
  File "/home/user/.local/lib/python3.6/site-packages/gunicorn/app/wsgiapp.py", line 48, in load_wsgiapp
    return util.import_app(self.app_uri)
  File "/home/user/.local/lib/python3.6/site-packages/gunicorn/util.py", line 359, in import_app
    mod = importlib.import_module(module)
  File "/usr/lib/python3.6/importlib/__init__.py", line 126, in import_module
    return _bootstrap._gcd_import(name[level:], package, level)
  File "<frozen importlib._bootstrap>", line 994, in _gcd_import
  File "<frozen importlib._bootstrap>", line 971, in _find_and_load
  File "<frozen importlib._bootstrap>", line 953, in _find_and_load_unlocked
ModuleNotFoundError: No module named 'service'
[2021-06-18 15:31:32 +0530] [29938] [INFO] Worker exiting (pid: 29938)
[2021-06-18 15:31:32 +0530] [29935] [INFO] Shutting down: Master
[2021-06-18 15:31:32 +0530] [29935] [INFO] Reason: Worker failed to boot.
[2021-06-18 15:31:36 +0530] [29939] [INFO] Starting gunicorn 20.1.0
[2021-06-18 15:31:36 +0530] [29939] [INFO] Listening at: http://127.0.0.1:8001 (29939)
[2021-06-18 15:31:36 +0530] [29939] [INFO] Using worker: sync
[2021-06-18 15:31:36 +0530] [29942] [INFO] Booting worker with pid: 29942
[2021-06-18 15:31:36 +0530] [29942] [ERROR] Exception in worker process
Traceback (most recent call last):
  File "/home/user/.local/lib/python3.6/site-packages/gunicorn/arbiter.py", line 589, in spawn_worker
    worker.init_process()
  File "/home/user/.local/lib/python3.6/site-packages/gunicorn/workers/base.py", line 134, in init_process
    self.load_wsgi()
  File "/home/user/.local/lib/python3.6/site-packages/gunicorn/workers/base.py", line 146, in load_wsgi
    self.wsgi = self.app.wsgi()
  File "/home/user/.local/lib/python3.6/site-packages/gunicorn/app/base.py", line 67, in wsgi
    self.callable = self.load()
  File "/home/user/.local/lib/python3.6/site-packages/gunicorn/app/wsgiapp.py", line 58, in load
    return self.load_wsgiapp()
  File "/home/user/.local/lib/python3.6/site-packages/gunicorn/app/wsgiapp.py", line 48, in load_wsgiapp
    return util.import_app(self.app_uri)
  File "/home/user/.local/lib/python3.6/site-packages/gunicorn/util.py", line 359, in import_app
    mod = importlib.import_module(module)
  File "/usr/lib/python3.6/importlib/__init__.py", line 126, in import_module
    return _bootstrap._gcd_import(name[level:], package, level)
  File "<frozen importlib._bootstrap>", line 994, in _gcd_import
  File "<frozen importlib._bootstrap>", line 971, in _find_and_load
  File "<frozen importlib._bootstrap>", line 953, in _find_and_load_unlocked
ModuleNotFoundError: No module named 'service'
[2021-06-18 15:31:36 +0530] [29942] [INFO] Worker exiting (pid: 29942)
[2021-06-18 15:31:36 +0530] [29939] [INFO] Shutting down: Master
[2021-06-18 15:31:36 +0530] [29939] [INFO] Reason: Worker failed to boot.
[2021-06-18 15:33:58 +0530] [29959] [INFO] Starting gunicorn 20.1.0
[2021-06-18 15:33:58 +0530] [29959] [INFO] Listening at: http://127.0.0.1:8001 (29959)
[2021-06-18 15:33:58 +0530] [29959] [INFO] Using worker: sync
[2021-06-18 15:33:58 +0530] [29964] [INFO] Booting worker with pid: 29964
[2021-06-18 15:33:58 +0530] [29964] [ERROR] Exception in worker process
Traceback (most recent call last):
  File "/home/user/.local/lib/python3.6/site-packages/gunicorn/arbiter.py", line 589, in spawn_worker
    worker.init_process()
  File "/home/user/.local/lib/python3.6/site-packages/gunicorn/workers/base.py", line 134, in init_process
    self.load_wsgi()
  File "/home/user/.local/lib/python3.6/site-packages/gunicorn/workers/base.py", line 146, in load_wsgi
    self.wsgi = self.app.wsgi()
  File "/home/user/.local/lib/python3.6/site-packages/gunicorn/app/base.py", line 67, in wsgi
    self.callable = self.load()
  File "/home/user/.local/lib/python3.6/site-packages/gunicorn/app/wsgiapp.py", line 58, in load
    return self.load_wsgiapp()
  File "/home/user/.local/lib/python3.6/site-packages/gunicorn/app/wsgiapp.py", line 48, in load_wsgiapp
    return util.import_app(self.app_uri)
  File "/home/user/.local/lib/python3.6/site-packages/gunicorn/util.py", line 359, in import_app
    mod = importlib.import_module(module)
  File "/usr/lib/python3.6/importlib/__init__.py", line 126, in import_module
    return _bootstrap._gcd_import(name[level:], package, level)
  File "<frozen importlib._bootstrap>", line 994, in _gcd_import
  File "<frozen importlib._bootstrap>", line 971, in _find_and_load
  File "<frozen importlib._bootstrap>", line 953, in _find_and_load_unlocked
ModuleNotFoundError: No module named 'service'
[2021-06-18 15:33:58 +0530] [29964] [INFO] Worker exiting (pid: 29964)
[2021-06-18 15:33:58 +0530] [29959] [INFO] Shutting down: Master
[2021-06-18 15:33:58 +0530] [29959] [INFO] Reason: Worker failed to boot.
[2021-06-18 15:34:00 +0530] [29965] [INFO] Starting gunicorn 20.1.0
[2021-06-18 15:34:00 +0530] [29965] [INFO] Listening at: http://127.0.0.1:8001 (29965)
[2021-06-18 15:34:00 +0530] [29965] [INFO] Using worker: sync
[2021-06-18 15:34:00 +0530] [29968] [INFO] Booting worker with pid: 29968
[2021-06-18 15:34:00 +0530] [29968] [ERROR] Exception in worker process
Traceback (most recent call last):
  File "/home/user/.local/lib/python3.6/site-packages/gunicorn/arbiter.py", line 589, in spawn_worker
    worker.init_process()
  File "/home/user/.local/lib/python3.6/site-packages/gunicorn/workers/base.py", line 134, in init_process
    self.load_wsgi()
  File "/home/user/.local/lib/python3.6/site-packages/gunicorn/workers/base.py", line 146, in load_wsgi
    self.wsgi = self.app.wsgi()
  File "/home/user/.local/lib/python3.6/site-packages/gunicorn/app/base.py", line 67, in wsgi
    self.callable = self.load()
  File "/home/user/.local/lib/python3.6/site-packages/gunicorn/app/wsgiapp.py", line 58, in load
    return self.load_wsgiapp()
  File "/home/user/.local/lib/python3.6/site-packages/gunicorn/app/wsgiapp.py", line 48, in load_wsgiapp
    return util.import_app(self.app_uri)
  File "/home/user/.local/lib/python3.6/site-packages/gunicorn/util.py", line 359, in import_app
    mod = importlib.import_module(module)
  File "/usr/lib/python3.6/importlib/__init__.py", line 126, in import_module
    return _bootstrap._gcd_import(name[level:], package, level)
  File "<frozen importlib._bootstrap>", line 994, in _gcd_import
  File "<frozen importlib._bootstrap>", line 971, in _find_and_load
  File "<frozen importlib._bootstrap>", line 953, in _find_and_load_unlocked
ModuleNotFoundError: No module named 'service'
[2021-06-18 15:34:00 +0530] [29968] [INFO] Worker exiting (pid: 29968)
[2021-06-18 15:34:00 +0530] [29965] [INFO] Shutting down: Master
[2021-06-18 15:34:00 +0530] [29965] [INFO] Reason: Worker failed to boot.
[2021-06-18 15:34:02 +0530] [29973] [INFO] Starting gunicorn 20.1.0
[2021-06-18 15:34:02 +0530] [29973] [INFO] Listening at: http://127.0.0.1:8001 (29973)
[2021-06-18 15:34:02 +0530] [29973] [INFO] Using worker: sync
[2021-06-18 15:34:02 +0530] [29976] [INFO] Booting worker with pid: 29976
[2021-06-18 15:34:02 +0530] [29976] [ERROR] Exception in worker process
Traceback (most recent call last):
  File "/home/user/.local/lib/python3.6/site-packages/gunicorn/arbiter.py", line 589, in spawn_worker
    worker.init_process()
  File "/home/user/.local/lib/python3.6/site-packages/gunicorn/workers/base.py", line 134, in init_process
    self.load_wsgi()
  File "/home/user/.local/lib/python3.6/site-packages/gunicorn/workers/base.py", line 146, in load_wsgi
    self.wsgi = self.app.wsgi()
  File "/home/user/.local/lib/python3.6/site-packages/gunicorn/app/base.py", line 67, in wsgi
    self.callable = self.load()
  File "/home/user/.local/lib/python3.6/site-packages/gunicorn/app/wsgiapp.py", line 58, in load
    return self.load_wsgiapp()
  File "/home/user/.local/lib/python3.6/site-packages/gunicorn/app/wsgiapp.py", line 48, in load_wsgiapp
    return util.import_app(self.app_uri)
  File "/home/user/.local/lib/python3.6/site-packages/gunicorn/util.py", line 359, in import_app
    mod = importlib.import_module(module)
  File "/usr/lib/python3.6/importlib/__init__.py", line 126, in import_module
    return _bootstrap._gcd_import(name[level:], package, level)
  File "<frozen importlib._bootstrap>", line 994, in _gcd_import
  File "<frozen importlib._bootstrap>", line 971, in _find_and_load
  File "<frozen importlib._bootstrap>", line 953, in _find_and_load_unlocked
ModuleNotFoundError: No module named 'service'
[2021-06-18 15:34:02 +0530] [29976] [INFO] Worker exiting (pid: 29976)
[2021-06-18 15:34:02 +0530] [29973] [INFO] Shutting down: Master
[2021-06-18 15:34:02 +0530] [29973] [INFO] Reason: Worker failed to boot.
[2021-06-18 15:34:05 +0530] [29978] [INFO] Starting gunicorn 20.1.0
[2021-06-18 15:34:05 +0530] [29978] [INFO] Listening at: http://127.0.0.1:8001 (29978)
[2021-06-18 15:34:05 +0530] [29978] [INFO] Using worker: sync
[2021-06-18 15:34:05 +0530] [29981] [INFO] Booting worker with pid: 29981
[2021-06-18 15:34:05 +0530] [29981] [ERROR] Exception in worker process
Traceback (most recent call last):
  File "/home/user/.local/lib/python3.6/site-packages/gunicorn/arbiter.py", line 589, in spawn_worker
    worker.init_process()
  File "/home/user/.local/lib/python3.6/site-packages/gunicorn/workers/base.py", line 134, in init_process
    self.load_wsgi()
  File "/home/user/.local/lib/python3.6/site-packages/gunicorn/workers/base.py", line 146, in load_wsgi
    self.wsgi = self.app.wsgi()
  File "/home/user/.local/lib/python3.6/site-packages/gunicorn/app/base.py", line 67, in wsgi
    self.callable = self.load()
  File "/home/user/.local/lib/python3.6/site-packages/gunicorn/app/wsgiapp.py", line 58, in load
    return self.load_wsgiapp()
  File "/home/user/.local/lib/python3.6/site-packages/gunicorn/app/wsgiapp.py", line 48, in load_wsgiapp
    return util.import_app(self.app_uri)
  File "/home/user/.local/lib/python3.6/site-packages/gunicorn/util.py", line 359, in import_app
    mod = importlib.import_module(module)
  File "/usr/lib/python3.6/importlib/__init__.py", line 126, in import_module
    return _bootstrap._gcd_import(name[level:], package, level)
  File "<frozen importlib._bootstrap>", line 994, in _gcd_import
  File "<frozen importlib._bootstrap>", line 971, in _find_and_load
  File "<frozen importlib._bootstrap>", line 953, in _find_and_load_unlocked
ModuleNotFoundError: No module named 'service'
[2021-06-18 15:34:05 +0530] [29981] [INFO] Worker exiting (pid: 29981)
[2021-06-18 15:34:05 +0530] [29978] [INFO] Shutting down: Master
[2021-06-18 15:34:05 +0530] [29978] [INFO] Reason: Worker failed to boot.
